<?xml version="1.0" encoding="utf-8"?>
<!-- This URDF was automatically created by SolidWorks to URDF Exporter! Originally created by Stephen Brawner (brawner@gmail.com) 
     Commit Version: 1.6.0-1-g15f4949  Build Version: 1.6.7594.29634
     For more information, please see http://wiki.ros.org/sw_urdf_exporter -->
<robot
  name="mevius">
  <material
    name="body_material">
    <color
      rgba="0.898039215686275 0.917647058823529 0.929411764705882 1" />
  </material>
  <link
    name="base">
    <inertial>
      <origin
        xyz="-0.00288686344144184 0.00107022785703442 0.0628887711129525"
        rpy="0 0 0" />
      <mass
        value="7.46950563423809" />
      <inertia
        ixx="0.0225470144173874"
        ixy="6.77338278057453E-05"
        ixz="1.3345156658201E-05"
        iyy="0.0141949429794967"
        iyz="-0.000150290491462575"
        izz="0.0262581265108455" />
    </inertial>
    <visual>
      <origin
        xyz="0 0 0"
        rpy="0 0 0" />
      <geometry>
        <mesh
          filename="meshes/base.STL" />
      </geometry>
      <material
        name="body_material">
    </visual>
    <collision>
      <origin
        xyz="0 0 0"
        rpy="0 0 0" />
      <geometry>
        <mesh
          filename="meshes/base.STL" />
      </geometry>
    </collision>
  </link>
  <link
    name="FR_scapula">
    <inertial>
      <origin
        xyz="0.0516252305401659 0.0119000363955649 0.000134643082608681"
        rpy="0 0 0" />
      <mass
        value="0.79238908220585" />
      <inertia
        ixx="0.000663847662717084"
        ixy="-4.9368919369038E-05"
        ixz="-2.95042745376549E-07"
        iyy="0.000948238273558436"
        iyz="1.97899135325603E-07"
        izz="0.00062428850657169" />
    </inertial>
    <visual>
      <origin
        xyz="0 0 0"
        rpy="0 0 0" />
      <geometry>
        <mesh
          filename="meshes/FR_scapula.STL" />
      </geometry>
      <material
        name="body_material">
    </visual>
    <collision>
      <origin
        xyz="0 0 0"
        rpy="0 0 0" />
      <geometry>
        <mesh
          filename="meshes/FR_scapula.STL" />
      </geometry>
    </collision>
  </link>
  <joint
    name="FR_collar"
    type="revolute">
    <origin
      xyz="0.16405000000001 -0.0720000000000002 0.056500000000002"
      rpy="0 0 0" />
    <parent
      link="base" />
    <child
      link="FR_scapula" />
    <axis
      xyz="1 0 0" />
    <limit
      lower="-0.7854"
      upper="0.7854"
      effort="25"
      velocity="500" />
  </joint>
  <link
    name="FR_thigh">
    <inertial>
      <origin
        xyz="-0.00458315732717235 -0.0450237251724228 -0.0462116341919131"
        rpy="0 0 0" />
      <mass
        value="1.28036049228712" />
      <inertia
        ixx="0.00466271860164795"
        ixy="6.08454654912399E-07"
        ixz="-8.7501983148644E-05"
        iyy="0.00514577751083402"
        iyz="-3.37691413998436E-06"
        izz="0.000733246177400886" />
    </inertial>
    <visual>
      <origin
        xyz="0 0 0"
        rpy="0 0 0" />
      <geometry>
        <mesh
          filename="meshes/FR_thigh.STL" />
      </geometry>
      <material
        name="body_material">
    </visual>
    <collision>
      <origin
        xyz="0 0 0"
        rpy="0 0 0" />
      <geometry>
        <mesh
          filename="meshes/FR_thigh.STL" />
      </geometry>
    </collision>
  </link>
  <joint
    name="FR_hip"
    type="revolute">
    <origin
      xyz="0.0555000000000021 -0.01205000000001 0"
      rpy="0 0 0" />
    <parent
      link="FR_scapula" />
    <child
      link="FR_thigh" />
    <axis
      xyz="0 1 0" />
    <limit
      lower="-1.5708"
      upper="1.5708"
      effort="25"
      velocity="500" />
  </joint>
  <link
    name="FR_calf">
    <inertial>
      <origin
        xyz="0.0061876 6.3449E-06 -0.096548"
        rpy="0 0 0" />
      <mass
        value="0.241966" />
      <inertia
        ixx="0.00125503"
        ixy="-12.1351E-09"
        ixz="-9.6374E-06"
        iyy="0.00125719"
        iyz="-21.3411E-08"
        izz="15.92E-06" />
    </inertial>
    <visual>
      <origin
        xyz="0 0 0"
        rpy="0 0 0" />
      <geometry>
        <mesh
          filename="meshes/FR_calf.STL" />
      </geometry>
      <material
        name="body_material">
    </visual>
    <collision>
      <origin
        xyz="0 0 0"
        rpy="0 0 0" />
      <geometry>
        <mesh
          filename="meshes/FR_calf.STL" />
      </geometry>
    </collision>
  </link>
  <joint
    name="FR_knee"
    type="revolute">
    <origin
      xyz="0 -0.06555000000001 -0.250000000000004"
      rpy="0 0 0" />
    <parent
      link="FR_thigh" />
    <child
      link="FR_calf" />
    <axis
      xyz="0 1 0" />
    <dynamics damping="0" friction="0.1"/>
    <!-- upper: "-0.7095" to "-1.0" -->
    <limit
      lower="-2.8856"
      upper="-1.0"
      effort="25"
      velocity="500" />
  </joint>
  <link name="FL_foot">
    <visual>
      <origin rpy="0 0 0" xyz="0 0 0"/>
      <geometry>
        <sphere radius="0.01"/>
      </geometry>
      <material
        name="body_material">
    </visual>
    <collision>
      <origin rpy="0 0 0" xyz="0 0 0"/>
      <geometry>
        <sphere radius="0.02"/>
      </geometry>
    </collision>
    <inertial>
      <mass value="0.06"/>
      <inertia ixx="9.6e-06" ixy="0.0" ixz="0.0" iyy="9.6e-06" iyz="0.0" izz="9.6e-06"/>
    </inertial>
  </link>
  <joint name="FL_foot_fixed" type="fixed">
    <origin rpy="0 0 0" xyz="0 0 -0.2"/>
    <parent link="FL_calf"/>
    <child link="FL_foot"/>
  </joint>
  <link
    name="FL_scapula">
    <inertial>
      <origin
        xyz="0.0516252305401659 -0.0119000363955648 0.000157365462420407"
        rpy="0 0 0" />
      <mass
        value="0.792389082205849" />
      <inertia
        ixx="0.000663847662717087"
        ixy="4.93689193690379E-05"
        ixz="-8.50139610992199E-07"
        iyy="0.000948238273558436"
        iyz="1.9750355102701E-07"
        izz="0.00062428850657169" />
    </inertial>
    <visual>
      <origin
        xyz="0 0 0"
        rpy="0 0 0" />
      <geometry>
        <mesh
          filename="meshes/FL_scapula.STL" />
      </geometry>
      <material
        name="body_material">
    </visual>
    <collision>
      <origin
        xyz="0 0 0"
        rpy="0 0 0" />
      <geometry>
        <mesh
          filename="meshes/FL_scapula.STL" />
      </geometry>
    </collision>
  </link>
  <joint
    name="FL_collar"
    type="revolute">
    <origin
      xyz="0.16405000000001 0.0719999999999999 0.0565000346699527"
      rpy="0 0 0" />
    <parent
      link="base" />
    <child
      link="FL_scapula" />
    <axis
      xyz="1 0 0" />
    <limit
      lower="-0.7854"
      upper="0.7854"
      effort="25"
      velocity="500" />
  </joint>
  <link
    name="FL_thigh">
    <inertial>
      <origin
        xyz="-0.0045959954184496 0.0450237251724227 -0.046226339333429"
        rpy="0 0 0" />
      <mass
        value="1.28036049228712" />
      <inertia
        ixx="0.00466307567078295"
        ixy="-5.39808976991609E-07"
        ixz="-8.89894514680999E-05"
        iyy="0.00514577751083402"
        iyz="3.72527450770942E-06"
        izz="0.000732889108265882" />
    </inertial>
    <visual>
      <origin
        xyz="0 0 0"
        rpy="0 0 0" />
      <geometry>
        <mesh
          filename="meshes/FL_thigh.STL" />
      </geometry>
      <material
        name="body_material">
    </visual>
    <collision>
      <origin
        xyz="0 0 0"
        rpy="0 0 0" />
      <geometry>
        <mesh
          filename="meshes/FL_thigh.STL" />
      </geometry>
    </collision>
  </link>
  <joint
    name="FL_hip"
    type="revolute">
    <origin
      xyz="0.0555000000000055 0.01205000000001 0"
      rpy="0 0 0" />
    <parent
      link="FL_scapula" />
    <child
      link="FL_thigh" />
    <axis
      xyz="0 1 0" />
    <limit
      lower="-1.5708"
      upper="1.5708"
      effort="25"
      velocity="500" />
  </joint>
  <link
    name="FL_calf">
    <inertial>
      <origin
        xyz="0.0061876 6.3449E-06 -0.096548"
        rpy="0 0 0" />
      <mass
        value="0.241966" />
      <inertia
        ixx="0.00125503"
        ixy="-12.1351E-09"
        ixz="-9.6374E-06"
        iyy="0.00125719"
        iyz="-21.3411E-08"
        izz="15.92E-06" />
    </inertial>
    <visual>
      <origin
        xyz="0 0 0"
        rpy="0 0 0" />
      <geometry>
        <mesh
          filename="meshes/FL_calf.STL" />
      </geometry>
      <material
        name="body_material">
    </visual>
    <collision>
      <origin
        xyz="0 0 0"
        rpy="0 0 0" />
      <geometry>
        <mesh
          filename="meshes/FL_calf.STL" />
      </geometry>
    </collision>
  </link>
  <joint
    name="FL_knee"
    type="revolute">
    <origin
      xyz="0 0.06555000000001 -0.249999999999998"
      rpy="0 0 0" />
    <parent
      link="FL_thigh" />
    <child
      link="FL_calf" />
    <axis
      xyz="0 1 0" />
    <dynamics damping="0" friction="0.1"/>
    <!-- upper: "-0.7095" to "-1.0" -->
    <limit
      lower="-2.8856"
      upper="-1.0"
      effort="25"
      velocity="500" />
  </joint>
  <link name="FL_foot">
    <visual>
      <origin rpy="0 0 0" xyz="0 0 0"/>
      <geometry>
        <sphere radius="0.01"/>
      </geometry>
      <material
        name="body_material">
    </visual>
    <collision>
      <origin rpy="0 0 0" xyz="0 0 0"/>
      <geometry>
        <sphere radius="0.02"/>
      </geometry>
    </collision>
    <inertial>
      <mass value="0.06"/>
      <inertia ixx="9.6e-06" ixy="0.0" ixz="0.0" iyy="9.6e-06" iyz="0.0" izz="9.6e-06"/>
    </inertial>
  </link>
  <joint name="FL_foot_fixed" type="fixed">
    <origin rpy="0 0 0" xyz="0 0 -0.2"/>
    <parent link="FL_calf"/>
    <child link="FL_foot"/>
  </joint>
  <link
    name="BR_scapula">
    <inertial>
      <origin
        xyz="-0.051625 0.0119 -0.00013464"
        rpy="0 0 0" />
      <mass
        value="0.79239" />
      <inertia
        ixx="0.00066385"
        ixy="4.9369E-05"
        ixz="-2.9504E-07"
        iyy="0.00094824"
        iyz="-1.979E-07"
        izz="0.00062429" />
    </inertial>
    <visual>
      <origin
        xyz="0 0 0"
        rpy="0 0 0" />
      <geometry>
        <mesh
          filename="meshes/BR_scapula.STL" />
      </geometry>
      <material
        name="body_material">
    </visual>
    <collision>
      <origin
        xyz="0 0 0"
        rpy="0 0 0" />
      <geometry>
        <mesh
          filename="meshes/BR_scapula.STL" />
      </geometry>
    </collision>
  </link>
  <joint
    name="BR_collar"
    type="revolute">
    <origin
      xyz="-0.16405000000001 -0.0719999999999995 0.0565000000000019"
      rpy="0 0 0" />
    <parent
      link="base" />
    <child
      link="BR_scapula" />
    <axis
      xyz="1 0 0" />
    <limit
      lower="-0.7854"
      upper="0.7854"
      effort="25"
      velocity="500" />
  </joint>
  <link
    name="BR_thigh">
    <inertial>
      <origin
        xyz="-0.0038406 -0.045024 -0.046019"
        rpy="0 0 0" />
      <mass
        value="1.2804" />
      <inertia
        ixx="0.004663"
        ixy="-8.4434E-07"
        ixz="-8.8799E-05"
        iyy="0.0051458"
        iyz="-3.5662E-06"
        izz="0.00073299" />
    </inertial>
    <visual>
      <origin
        xyz="0 0 0"
        rpy="0 0 0" />
      <geometry>
        <mesh
          filename="meshes/BR_thigh.STL" />
      </geometry>
      <material
        name="body_material">
    </visual>
    <collision>
      <origin
        xyz="0 0 0"
        rpy="0 0 0" />
      <geometry>
        <mesh
          filename="meshes/BR_thigh.STL" />
      </geometry>
    </collision>
  </link>
  <joint
    name="BR_hip"
    type="revolute">
    <origin
      xyz="-0.0555000000000055 -0.01205000000001 0"
      rpy="0 0 0" />
    <parent
      link="BR_scapula" />
    <child
      link="BR_thigh" />
    <axis
      xyz="0 1 0" />
    <limit
      lower="-1.5708"
      upper="1.5708"
      effort="25"
      velocity="500" />
  </joint>
  <link
    name="BR_calf">
    <inertial>
      <origin
        xyz="0.0061876 6.3449E-06 -0.096548"
        rpy="0 0 0" />
      <mass
        value="0.241966" />
      <inertia
        ixx="0.000125503"
        ixy="-12.1351E-09"
        ixz="-9.6374E-06"
        iyy="0.00125719"
        iyz="-21.3411E-08"
        izz="15.92E-06" />
    </inertial>
    <visual>
      <origin
        xyz="0 0 0"
        rpy="0 0 0" />
      <geometry>
        <mesh
          filename="meshes/BR_calf.STL" />
      </geometry>
      <material
        name="body_material">
    </visual>
    <collision>
      <origin
        xyz="0 0 0"
        rpy="0 0 0" />
      <geometry>
        <mesh
          filename="meshes/BR_calf.STL" />
      </geometry>
    </collision>
  </link>
  <joint
    name="BR_knee"
    type="revolute">
    <origin
      xyz="0 -0.0655500000000101 -0.249999999999997"
      rpy="0 0 0" />
    <parent
      link="BR_thigh" />
    <child
      link="BR_calf" />
    <axis
      xyz="0 1 0" />
    <dynamics damping="0" friction="0.1"/>
    <!-- upper: "-0.7095" to "-1.0" -->
    <limit
      lower="-2.8856"
      upper="-1.0"
      effort="25"
      velocity="500" />
  </joint>
  <link name="BR_foot">
    <visual>
      <origin rpy="0 0 0" xyz="0 0 0"/>
      <geometry>
        <sphere radius="0.01"/>
      </geometry>
      <material
        name="body_material">
    </visual>
    <collision>
      <origin rpy="0 0 0" xyz="0 0 0"/>
      <geometry>
        <sphere radius="0.02"/>
      </geometry>
    </collision>
    <inertial>
      <mass value="0.06"/>
      <inertia ixx="9.6e-06" ixy="0.0" ixz="0.0" iyy="9.6e-06" iyz="0.0" izz="9.6e-06"/>
    </inertial>
  </link>
  <joint name="BR_foot_fixed" type="fixed">
    <origin rpy="0 0 0" xyz="0 0 -0.2"/>
    <parent link="BR_calf"/>
    <child link="BR_foot"/>
  </joint>
  <link
    name="BL_scapula">
    <inertial>
      <origin
        xyz="-0.0516252305401659 -0.0119000363955648 -0.000157365462420601"
        rpy="0 0 0" />
      <mass
        value="0.792389082205849" />
      <inertia
        ixx="0.000663847662717084"
        ixy="-4.93689193690379E-05"
        ixz="-8.50139610991644E-07"
        iyy="0.000948238273558437"
        iyz="-1.97503551027001E-07"
        izz="0.000624288506571688" />
    </inertial>
    <visual>
      <origin
        xyz="0 0 0"
        rpy="0 0 0" />
      <geometry>
        <mesh
          filename="meshes/BL_scapula.STL" />
      </geometry>
      <material
        name="body_material">
    </visual>
    <collision>
      <origin
        xyz="0 0 0"
        rpy="0 0 0" />
      <geometry>
        <mesh
          filename="meshes/BL_scapula.STL" />
      </geometry>
    </collision>
  </link>
  <joint
    name="BL_collar"
    type="revolute">
    <origin
      xyz="-0.16405000000001 0.0719999999999999 0.0564999653300497"
      rpy="0 0 0" />
    <parent
      link="base" />
    <child
      link="BL_scapula" />
    <axis
      xyz="1 0 0" />
    <limit
      lower="-0.7854"
      upper="0.7854"
      effort="25"
      velocity="500" />
  </joint>
  <link
    name="BL_thigh">
    <inertial>
      <origin
        xyz="-0.00390161717030679 0.0450237251724227 -0.0460663202075131"
        rpy="0 0 0" />
      <mass
        value="1.28036049228712" />
      <inertia
        ixx="0.00466272221096624"
        ixy="9.12989444199061E-07"
        ixz="-8.72356243582126E-05"
        iyy="0.00514577751083403"
        iyz="3.12373693962634E-06"
        izz="0.000733242568082601" />
    </inertial>
    <visual>
      <origin
        xyz="0 0 0"
        rpy="0 0 0" />
      <geometry>
        <mesh
          filename="meshes/BL_thigh.STL" />
      </geometry>
      <material
        name="body_material">
    </visual>
    <collision>
      <origin
        xyz="0 0 0"
        rpy="0 0 0" />
      <geometry>
        <mesh
          filename="meshes/BL_thigh.STL" />
      </geometry>
    </collision>
  </link>
  <joint
    name="BL_hip"
    type="revolute">
    <origin
      xyz="-0.0555000000000055 0.01205000000001 0"
      rpy="0 0 0" />
    <parent
      link="BL_scapula" />
    <child
      link="BL_thigh" />
    <axis
      xyz="0 1 0" />
    <limit
      lower="-1.5708"
      upper="1.5708"
      effort="25"
      velocity="500" />
  </joint>
  <link
    name="BL_calf">
    <inertial>
      <origin
        xyz="0.00618759954847875 6.34493544132697E-06 -0.0965481635934385"
        rpy="0 0 0" />
      <mass
        value="0.2419657771505335" />
      <inertia
        ixx="0.001255029962126553"
        ixy="-12.13510569780358E-09"
        ixz="-9.63738626871361E-06"
        iyy="0.001257192801864513"
        iyz="-21.34108614427503E-08"
        izz="15.91998101823404E-06" />
    </inertial>
    <visual>
      <origin
        xyz="0 0 0"
        rpy="0 0 0" />
      <geometry>
        <mesh
          filename="meshes/BL_calf.STL" />
      </geometry>
      <material
        name="body_material">
    </visual>
    <collision>
      <origin
        xyz="0 0 0"
        rpy="0 0 0" />
      <geometry>
        <mesh
          filename="meshes/BL_calf.STL" />
      </geometry>
    </collision>
  </link>
  <joint
    name="BL_knee"
    type="revolute">
    <origin
      xyz="0 0.06555 -0.25"
      rpy="0 0 0" />
    <parent
      link="BL_thigh" />
    <child
      link="BL_calf" />
    <axis
      xyz="0 1 0" />
    <dynamics damping="0" friction="0.1"/>
    <!-- upper: "-0.7095" to "-1.0" -->
    <limit
      lower="-2.8856"
      upper="-1.0"
      effort="25"
      velocity="500" />
  </joint>
  <link name="BL_foot">
    <visual>
      <origin rpy="0 0 0" xyz="0 0 0"/>
      <geometry>
        <sphere radius="0.01"/>
      </geometry>
      <material
        name="body_material">
    </visual>
    <collision>
      <origin rpy="0 0 0" xyz="0 0 0"/>
      <geometry>
        <sphere radius="0.02"/>
      </geometry>
    </collision>
    <inertial>
      <mass value="0.06"/>
      <inertia ixx="9.6e-06" ixy="0.0" ixz="0.0" iyy="9.6e-06" iyz="0.0" izz="9.6e-06"/>
    </inertial>
  </link>
  <joint name="BL_foot_fixed" type="fixed">
    <origin rpy="0 0 0" xyz="0 0 -0.2"/>
    <parent link="BL_calf"/>
    <child link="BL_foot"/>
  </joint>
</robot>
